<?xml version="1.0"?>
<robot xmlns:xacro="http://wiki.ros.org/xacro"
	name="ur5" >


	<link name="world" >
	</link>
	<link name="base_link" >
		<visual>
			<geometry>
				<mesh filename="package://ur_description/meshes/ur5/visual/base.dae" />
			</geometry>
		</visual>
		<collision>
			<geometry>
				<mesh filename="package://ur_description/meshes/ur5/collision/base.stl" />
			</geometry>
		</collision>
		<inertial>
			<mass value="4.0">
			<origin xyz="0 0 0" rpy="0 0 0" />
			<inertia ixx="0.004433" ixy="0.0" ixz="0.0"
				iyy="0.004433" iyz="0.0"
				izz="0.0072" />
		</inertial>
	</link>
	<link name="base" >
	</link>
	<link name="shoulder_link" >
		<visual>
			<geometry>
				<mesh filename="package://ur_description/meshes/ur5/visual/shoulder.dae" />
			</geometry>
		</visual>
		<collision>
			<geometry>
				<mesh filename="package://ur_description/meshes/ur5/collision/shoulder.stl" />
			</geometry>
		</collision>
		<inertial>
			<mass value="3.7">
			<origin xyz="0 0 0" rpy="0 0 0" />
			<inertia ixx="0.010267" ixy="0.0" ixz="0.0"
				iyy="0.010267" iyz="0.0"
				izz="0.00666" />
		</inertial>
	</link>
	<link name="upper_arm_link" >
		<visual>
			<geometry>
				<mesh filename="package://ur_description/meshes/ur5/visual/upperarm.dae" />
			</geometry>
		</visual>
		<collision>
			<geometry>
				<mesh filename="package://ur_description/meshes/ur5/collision/upperarm.stl" />
			</geometry>
		</collision>
		<inertial>
			<mass value="8.393">
			<origin xyz="0.000000 0.000000 0.280000" rpy="0 0 0" />
			<inertia ixx="0.226891" ixy="0.0" ixz="0.0"
				iyy="0.226891" iyz="0.0"
				izz="0.015107" />
		</inertial>
	</link>
	<link name="forearm_link" >
		<visual>
			<geometry>
				<mesh filename="package://ur_description/meshes/ur5/visual/forearm.dae" />
			</geometry>
		</visual>
		<collision>
			<geometry>
				<mesh filename="package://ur_description/meshes/ur5/collision/forearm.stl" />
			</geometry>
		</collision>
		<inertial>
			<mass value="2.275">
			<origin xyz="0.000000 0.000000 0.196125" rpy="0 0 0" />
			<inertia ixx="0.031217" ixy="0.0" ixz="0.0"
				iyy="0.031217" iyz="0.0"
				izz="0.004095" />
		</inertial>
	</link>
	<link name="wrist_1_link" >
		<visual>
			<geometry>
				<mesh filename="package://ur_description/meshes/ur5/visual/wrist1.dae" />
			</geometry>
		</visual>
		<collision>
			<geometry>
				<mesh filename="package://ur_description/meshes/ur5/collision/wrist1.stl" />
			</geometry>
		</collision>
		<inertial>
			<mass value="1.219">
			<origin xyz="0.000000 0.093000 0.000000" rpy="0 0 0" />
			<inertia ixx="0.00256" ixy="0.0" ixz="0.0"
				iyy="0.00256" iyz="0.0"
				izz="0.002194" />
		</inertial>
	</link>
	<link name="wrist_2_link" >
		<visual>
			<geometry>
				<mesh filename="package://ur_description/meshes/ur5/visual/wrist2.dae" />
			</geometry>
		</visual>
		<collision>
			<geometry>
				<mesh filename="package://ur_description/meshes/ur5/collision/wrist2.stl" />
			</geometry>
		</collision>
		<inertial>
			<mass value="1.219">
			<origin xyz="0.000000 0.000000 0.094650" rpy="0 0 0" />
			<inertia ixx="0.00256" ixy="0.0" ixz="0.0"
				iyy="0.00256" iyz="0.0"
				izz="0.002194" />
		</inertial>
	</link>
	<link name="wrist_3_link" >
		<visual>
			<geometry>
				<mesh filename="package://ur_description/meshes/ur5/visual/wrist3.dae" />
			</geometry>
		</visual>
		<collision>
			<geometry>
				<mesh filename="package://ur_description/meshes/ur5/collision/wrist3.stl" />
			</geometry>
		</collision>
		<inertial>
			<mass value="0.1879">
			<origin xyz="0.000000 0.065050 0.000000" rpy="1.570796 -0.000000 0.000000" />
			<inertia ixx="8.5E-5" ixy="0.0" ixz="0.0"
				iyy="8.5E-5" iyz="0.0"
				izz="1.32E-4" />
		</inertial>
	</link>
	<link name="ee_link" >
		<collision>
			<geometry>
				<box size="0.010000 0.010000 0.010000" />
			</geometry>
		</collision>
	</link>
	<link name="tool0" >
	</link>
	
	<joint name="world_joint" type="fixed">
		<parent link="world" />
		<child link="base_link" />
	</joint>
	<joint name="base_link_base_fixed_joint" type="fixed">
		<parent link="base_link" />
		<child link="base" />
	</joint>
	<joint name="shoulder_pan_joint" type="revolute">
		<parent link="base_link" />
		<child link="shoulder_link" />
		<axis xyz="0.000000 0.000000 1.000000">
	</joint>
	<joint name="shoulder_lift_joint" type="revolute">
		<parent link="shoulder_link" />
		<child link="upper_arm_link" />
		<origin xyz="0.000000 0.135850 0.000000" rpy="0.000000 1.570796 -0.000000"/>
		<axis xyz="0.000000 1.000000 0.000000">
	</joint>
	<joint name="elbow_joint" type="revolute">
		<parent link="upper_arm_link" />
		<child link="forearm_link" />
		<axis xyz="0.000000 1.000000 0.000000">
	</joint>
	<joint name="wrist_1_joint" type="revolute">
		<parent link="forearm_link" />
		<child link="wrist_1_link" />
		<origin xyz="0.000000 0.000000 0.392250" rpy="0.000000 1.570796 -0.000000"/>
		<axis xyz="0.000000 1.000000 0.000000">
	</joint>
	<joint name="wrist_2_joint" type="revolute">
		<parent link="wrist_1_link" />
		<child link="wrist_2_link" />
		<axis xyz="0.000000 0.000000 1.000000">
	</joint>
	<joint name="wrist_3_joint" type="revolute">
		<parent link="wrist_2_link" />
		<child link="wrist_3_link" />
		<axis xyz="0.000000 1.000000 0.000000">
	</joint>
	<joint name="ee_fixed_joint" type="fixed">
		<parent link="wrist_3_link" />
		<child link="ee_link" />
		<origin xyz="0.000000 0.082300 0.000000" rpy="0.000000 -0.000000 1.570796"/>
	</joint>
	<joint name="wrist_3_link_tool0_fixed_joint" type="fixed">
		<parent link="wrist_3_link" />
		<child link="tool0" />
		<origin xyz="0.000000 0.082300 0.000000" rpy="-1.570796 0.000000 0.000000"/>
	</joint>

</robot>
