<?xml version="1.0" ?>
<!-- =================================================================================== -->
<!-- |    This document was autogenerated by xacro from kr16.xacro                     | -->
<!-- |    EDITING THIS FILE BY HAND IS NOT RECOMMENDED                                 | -->
<!-- =================================================================================== -->
<robot name="kr16">
  <link name="kr16_base_link">
    <visual>
      <geometry>
        <mesh filename="package://kuka_kr16_support/meshes/kr16_2/visual/base_link.dae"/>
      </geometry>
    </visual>
    <collision>
      <geometry>
        <mesh filename="package://kuka_kr16_support/meshes/kr16_2/collision/base_link.stl"/>
      </geometry>
    </collision>
    <inertial>
      <mass value="2.0"/>
      <origin rpy="0 0 0" xyz="0 0 0"/>
      <inertia ixx="0.01" ixy="0.0" ixz="0.0" iyy="0.01" iyz="0.0" izz="0.01"/>
    </inertial>
  </link>
  <link name="kr16_link_1">
    <visual>
      <geometry>
        <mesh filename="package://kuka_kr16_support/meshes/kr16_2/visual/link_1.dae"/>
      </geometry>
    </visual>
    <collision>
      <geometry>
        <mesh filename="package://kuka_kr16_support/meshes/kr16_2/collision/link_1.stl"/>
      </geometry>
    </collision>
    <inertial>
      <mass value="2.0"/>
      <origin rpy="0 0 0" xyz="0 0 0"/>
      <inertia ixx="0.01" ixy="0.0" ixz="0.0" iyy="0.01" iyz="0.0" izz="0.01"/>
    </inertial>
  </link>
  <link name="kr16_link_2">
    <visual>
      <geometry>
        <mesh filename="package://kuka_kr16_support/meshes/kr16_2/visual/link_2.dae"/>
      </geometry>
    </visual>
    <collision>
      <geometry>
        <mesh filename="package://kuka_kr16_support/meshes/kr16_2/collision/link_2.stl"/>
      </geometry>
    </collision>
    <inertial>
      <mass value="2.0"/>
      <origin rpy="0 0 0" xyz="0 0 0"/>
      <inertia ixx="0.01" ixy="0.0" ixz="0.0" iyy="0.01" iyz="0.0" izz="0.01"/>
    </inertial>
  </link>
  <link name="kr16_link_3">
    <visual>
      <geometry>
        <mesh filename="package://kuka_kr16_support/meshes/kr16_2/visual/link_3.dae"/>
      </geometry>
    </visual>
    <collision>
      <geometry>
        <mesh filename="package://kuka_kr16_support/meshes/kr16_2/collision/link_3.stl"/>
      </geometry>
    </collision>
    <inertial>
      <mass value="2.0"/>
      <origin rpy="0 0 0" xyz="0 0 0"/>
      <inertia ixx="0.01" ixy="0.0" ixz="0.0" iyy="0.01" iyz="0.0" izz="0.01"/>
    </inertial>
  </link>
  <link name="kr16_link_4">
    <visual>
      <geometry>
        <mesh filename="package://kuka_kr16_support/meshes/kr16_2/visual/link_4.dae"/>
      </geometry>
    </visual>
    <collision>
      <geometry>
        <mesh filename="package://kuka_kr16_support/meshes/kr16_2/collision/link_4.stl"/>
      </geometry>
    </collision>
    <inertial>
      <mass value="2.0"/>
      <origin rpy="0 0 0" xyz="0 0 0"/>
      <inertia ixx="0.01" ixy="0.0" ixz="0.0" iyy="0.01" iyz="0.0" izz="0.01"/>
    </inertial>
  </link>
  <link name="kr16_link_5">
    <visual>
      <geometry>
        <mesh filename="package://kuka_kr16_support/meshes/kr16_2/visual/link_5.dae"/>
      </geometry>
    </visual>
    <collision>
      <geometry>
        <mesh filename="package://kuka_kr16_support/meshes/kr16_2/collision/link_5.stl"/>
      </geometry>
    </collision>
    <inertial>
      <mass value="2.0"/>
      <origin rpy="0 0 0" xyz="0 0 0"/>
      <inertia ixx="0.01" ixy="0.0" ixz="0.0" iyy="0.01" iyz="0.0" izz="0.01"/>
    </inertial>
  </link>
  <link name="kr16_link_6">
    <visual>
      <geometry>
        <mesh filename="package://kuka_kr16_support/meshes/kr16_2/visual/link_6.dae"/>
      </geometry>
    </visual>
    <collision>
      <geometry>
        <mesh filename="package://kuka_kr16_support/meshes/kr16_2/collision/link_6.stl"/>
      </geometry>
    </collision>
    <inertial>
      <mass value="2.0"/>
      <origin rpy="0 0 0" xyz="0 0 0"/>
      <inertia ixx="0.01" ixy="0.0" ixz="0.0" iyy="0.01" iyz="0.0" izz="0.01"/>
    </inertial>
  </link>
  <link name="kr16_flange">
		</link>
  <link name="kr16_base">
		</link>
  <link name="kr16_tool0">
		</link>
  <joint name="kr16_joint_a1" type="revolute">
    <parent link="kr16_base_link"/>
    <child link="kr16_link_1"/>
    <origin rpy="0 0 0" xyz="0 0 0.675"/>
    <axis xyz="0 0 -1"/>
  </joint>
  <joint name="kr16_joint_a2" type="revolute">
    <parent link="kr16_link_1"/>
    <child link="kr16_link_2"/>
    <origin rpy="0 0 0" xyz="0.26 0 0"/>
    <axis xyz="0 1 0"/>
  </joint>
  <joint name="kr16_joint_a3" type="revolute">
    <parent link="kr16_link_2"/>
    <child link="kr16_link_3"/>
    <origin rpy="0 0 0" xyz="0.68 0 0"/>
    <axis xyz="0 1 0"/>
  </joint>
  <joint name="kr16_joint_a4" type="revolute">
    <parent link="kr16_link_3"/>
    <child link="kr16_link_4"/>
    <origin rpy="0 0 0" xyz="0.67 0 -0.035"/>
    <axis xyz="-1 0 0"/>
  </joint>
  <joint name="kr16_joint_a5" type="revolute">
    <parent link="kr16_link_4"/>
    <child link="kr16_link_5"/>
    <origin rpy="0 0 0" xyz="0 0 0"/>
    <axis xyz="0 1 0"/>
  </joint>
  <joint name="kr16_joint_a6" type="revolute">
    <parent link="kr16_link_5"/>
    <child link="kr16_link_6"/>
    <origin rpy="0 0 0" xyz="0 0 0.675"/>
  </joint>
  <joint name="kr16_joint_a6_flange" type="revolute">
    <parent link="kr16_link_6"/>
    <child link="kr16_flange"/>
    <origin rpy="0 0 0" xyz="0.158 0 0"/>
    <axis xyz="-1 0 0"/>
  </joint>
  <joint name="kr16_base_link_base" type="revolute">
    <parent link="kr16_base_link"/>
    <child link="kr16_base"/>
    <origin rpy="0 0 0" xyz="0 0 0.675"/>
  </joint>
  <joint name="kr16_flange_tool0" type="revolute">
    <parent link="kr16_flange"/>
    <child link="kr16_tool0"/>
    <origin rpy="0 1.5707963267948966 0" xyz="0 0 0"/>
  </joint>
  <link name="axia80_adapter_robotside_flange">
		</link>
  <link name="axia80_adapter_robotside_changer">
		</link>
  <joint name="axia80_adapter_robotside_flange_joint" type="fixed">
    <parent link="kr16_tool0"/>
    <child link="axia80_adapter_robotside_flange"/>
    <origin rpy="0 0 1.5707963267948966" xyz="0 0 0"/>
  </joint>
  <joint name="axia80_adapter_robotside_changer_joint" type="fixed">
    <parent link="axia80_adapter_robotside_flange"/>
    <child link="axia80_adapter_robotside_changer"/>
    <origin rpy="0 0 0" xyz="0 0 0.01"/>
  </joint>
  <link name="axia80_adapter_robotside_changer_sensor">
    <visual>
      <geometry>
        <mesh filename="package://schrauber_description/mesh/Aufnahme_FT_Sensor_origin.STL"/>
      </geometry>
    </visual>
  </link>
  <link name="axia80_adapter_robotside_sensor">
		</link>
  <joint name="axia80_adapter_robotside_changer_sensor_joint" type="fixed">
    <parent link="axia80_adapter_robotside_changer"/>
    <child link="axia80_adapter_robotside_changer_sensor"/>
    <origin rpy="0 0 0" xyz="0 0 0"/>
  </joint>
  <joint name="axia80_adapter_robotside_sensor_joint" type="fixed">
    <parent link="axia80_adapter_robotside_changer_sensor"/>
    <child link="axia80_adapter_robotside_sensor"/>
    <origin rpy="0 0 0" xyz="0 0 0.01"/>
  </joint>
  <link name="ati_axia80_robotside">
    <visual>
      <geometry>
        <mesh filename="package://ati_force_sensor/urdf/mesh/ATI-9105-Axia80-M20.stl"/>
      </geometry>
    </visual>
  </link>
  <link name="ati_axia80_toolside">
		</link>
  <link name="ati_axia80_force_sensor_frame">
		</link>
  <joint name="ati_axia80_robotside_joint" type="fixed">
    <parent link="axia80_adapter_robotside_sensor"/>
    <child link="ati_axia80_robotside"/>
    <origin rpy="0 0 0" xyz="0 0 0"/>
  </joint>
  <joint name="ati_axia80_toolside_joint" type="fixed">
    <parent link="ati_axia80_robotside"/>
    <child link="ati_axia80_toolside"/>
    <origin rpy="0 0 0.0254" xyz="0 0 0"/>
  </joint>
  <joint name="ati_axia80_measurement_joint" type="fixed">
    <parent link="ati_axia80_toolside"/>
    <child link="ati_axia80_force_sensor_frame"/>
    <origin rpy="0 0 0" xyz="0 0 0"/>
  </joint>
  <link name="axia80_adapter_toolside_sensor">
		</link>
  <link name="axia80_adapter_toolside_changer_sensor">
		</link>
  <joint name="axia80_adapter_toolside_sensor_joint" type="fixed">
    <parent link="ati_axia80_toolside"/>
    <child link="axia80_adapter_toolside_changer_sensor"/>
    <origin rpy="0 0 0" xyz="0 0 0"/>
  </joint>
  <joint name="axia80_adapter_toolside_sensor_changer_joint" type="fixed">
    <parent link="axia80_adapter_toolside_sensor"/>
    <child link="axia80_adapter_robotside_changer_sensor"/>
    <origin rpy="0 0 0" xyz="0 0 0.01"/>
  </joint>
  <link name="table_big">
	</link>
  <link name="weldingtable">
	</link>
  <joint name="table_joint" type="fixed">
    <parent link="table_big"/>
    <child link="kr16_base_link"/>
    <origin rpy="0 0 -2.356194490192345" xyz="0.858 0.863 -0.405"/>
  </joint>
  <joint name="weldingtable_joint" type="fixed">
    <parent link="table_big"/>
    <child link="weldingtable"/>
    <origin rpy="0 0 1.5707963267948966" xyz="-0.0254 0.07 0.035"/>
  </joint>
</robot>
