<?xml version="1.0"?>
<robot xmlns:xacro="http://wiki.ros.org/xacro" name="kr16_2_macro" >


	<xacro:macro name="kuka_kr16_2" params="prefix ">
		<link name="${prefix}base_link" >
			<visual>
				<geometry>
					<mesh filename="package://kuka_kr16_support/meshes/kr16_2/visual/base_link.dae" />
				</geometry>
			</visual>
			<collision>
				<geometry>
					<mesh filename="package://kuka_kr16_support/meshes/kr16_2/collision/base_link.stl" />
				</geometry>
			</collision>
			<inertial>
				<mass value="2.0">
				<origin xyz="0 0 0" rpy="0 0 0" />
				<inertia ixx="0.01" ixy="0.0" ixz="0.0"
					iyy="0.01" iyz="0.0"
					izz="0.01" />
			</inertial>
		</link>
		<link name="${prefix}link_1" >
			<visual>
				<geometry>
					<mesh filename="package://kuka_kr16_support/meshes/kr16_2/visual/link_1.dae" />
				</geometry>
			</visual>
			<collision>
				<geometry>
					<mesh filename="package://kuka_kr16_support/meshes/kr16_2/collision/link_1.stl" />
				</geometry>
			</collision>
			<inertial>
				<mass value="2.0">
				<origin xyz="0 0 0" rpy="0 0 0" />
				<inertia ixx="0.01" ixy="0.0" ixz="0.0"
					iyy="0.01" iyz="0.0"
					izz="0.01" />
			</inertial>
		</link>
		<link name="${prefix}link_2" >
			<visual>
				<geometry>
					<mesh filename="package://kuka_kr16_support/meshes/kr16_2/visual/link_2.dae" />
				</geometry>
			</visual>
			<collision>
				<geometry>
					<mesh filename="package://kuka_kr16_support/meshes/kr16_2/collision/link_2.stl" />
				</geometry>
			</collision>
			<inertial>
				<mass value="2.0">
				<origin xyz="0 0 0" rpy="0 0 0" />
				<inertia ixx="0.01" ixy="0.0" ixz="0.0"
					iyy="0.01" iyz="0.0"
					izz="0.01" />
			</inertial>
		</link>
		<link name="${prefix}link_3" >
			<visual>
				<geometry>
					<mesh filename="package://kuka_kr16_support/meshes/kr16_2/visual/link_3.dae" />
				</geometry>
			</visual>
			<collision>
				<geometry>
					<mesh filename="package://kuka_kr16_support/meshes/kr16_2/collision/link_3.stl" />
				</geometry>
			</collision>
			<inertial>
				<mass value="2.0">
				<origin xyz="0 0 0" rpy="0 0 0" />
				<inertia ixx="0.01" ixy="0.0" ixz="0.0"
					iyy="0.01" iyz="0.0"
					izz="0.01" />
			</inertial>
		</link>
		<link name="${prefix}link_4" >
			<visual>
				<geometry>
					<mesh filename="package://kuka_kr16_support/meshes/kr16_2/visual/link_4.dae" />
				</geometry>
			</visual>
			<collision>
				<geometry>
					<mesh filename="package://kuka_kr16_support/meshes/kr16_2/collision/link_4.stl" />
				</geometry>
			</collision>
			<inertial>
				<mass value="2.0">
				<origin xyz="0 0 0" rpy="0 0 0" />
				<inertia ixx="0.01" ixy="0.0" ixz="0.0"
					iyy="0.01" iyz="0.0"
					izz="0.01" />
			</inertial>
		</link>
		<link name="${prefix}link_5" >
			<visual>
				<geometry>
					<mesh filename="package://kuka_kr16_support/meshes/kr16_2/visual/link_5.dae" />
				</geometry>
			</visual>
			<collision>
				<geometry>
					<mesh filename="package://kuka_kr16_support/meshes/kr16_2/collision/link_5.stl" />
				</geometry>
			</collision>
			<inertial>
				<mass value="2.0">
				<origin xyz="0 0 0" rpy="0 0 0" />
				<inertia ixx="0.01" ixy="0.0" ixz="0.0"
					iyy="0.01" iyz="0.0"
					izz="0.01" />
			</inertial>
		</link>
		<link name="${prefix}link_6" >
			<visual>
				<geometry>
					<mesh filename="package://kuka_kr16_support/meshes/kr16_2/visual/link_6.dae" />
				</geometry>
			</visual>
			<collision>
				<geometry>
					<mesh filename="package://kuka_kr16_support/meshes/kr16_2/collision/link_6.stl" />
				</geometry>
			</collision>
			<inertial>
				<mass value="2.0">
				<origin xyz="0 0 0" rpy="0 0 0" />
				<inertia ixx="0.01" ixy="0.0" ixz="0.0"
					iyy="0.01" iyz="0.0"
					izz="0.01" />
			</inertial>
		</link>
		<link name="${prefix}flange" >
		</link>
		<link name="${prefix}base" >
		</link>
		<link name="${prefix}tool0" >
		</link>
		<joint name="${prefix}joint_a1" type="revolute">
			<parent link="${prefix}base_link" />
			<child link="${prefix}link_1" />
			<origin xyz="0 0 0.675" rpy="0 0 0" />
			<axis xyz="0 0 -1">
		</joint>
		<joint name="${prefix}joint_a2" type="revolute">
			<parent link="${prefix}link_1" />
			<child link="${prefix}link_2" />
			<origin xyz="0.26 0 0" rpy="0 0 0" />
			<axis xyz="0 1 0">
		</joint>
		<joint name="${prefix}joint_a3" type="revolute">
			<parent link="${prefix}link_2" />
			<child link="${prefix}link_3" />
			<origin xyz="0.68 0 0" rpy="0 0 0" />
			<axis xyz="0 1 0">
		</joint>
		<joint name="${prefix}joint_a4" type="revolute">
			<parent link="${prefix}link_3" />
			<child link="${prefix}link_4" />
			<origin xyz="0.67 0 -0.035" rpy="0 0 0" />
			<axis xyz="-1 0 0">
		</joint>
		<joint name="${prefix}joint_a5" type="revolute">
			<parent link="${prefix}link_4" />
			<child link="${prefix}link_5" />
			<origin xyz="0 0 0" rpy="0 0 0" />
			<axis xyz="0 1 0">
		</joint>
		<joint name="${prefix}joint_a6" type="revolute">
			<parent link="${prefix}link_5" />
			<child link="${prefix}link_6" />
			<origin xyz="0 0 0.675" rpy="0 0 0" />
		</joint>
		<joint name="${prefix}joint_a6_flange" type="revolute">
			<parent link="${prefix}link_6" />
			<child link="${prefix}flange" />
			<origin xyz="0.158 0 0" rpy="0 0 0" />
			<axis xyz="-1 0 0">
		</joint>
		<joint name="${prefix}base_link_base" type="revolute">
			<parent link="${prefix}base_link" />
			<child link="${prefix}base" />
			<origin xyz="0 0 0.675" rpy="0 0 0" />
		</joint>
		<joint name="${prefix}flange_tool0" type="revolute">
			<parent link="${prefix}flange" />
			<child link="${prefix}tool0" />
			<origin xyz="0 0 0" rpy="0 ${radians(90)} 0" />
		</joint>
	</xacro:macro>

</robot>
